Workbook

Sheet Cover
B2: Space Exploration Technologies Corp. (Nasdaq: SPCX)
B3: P&L Business Case Model
B4: Actuals through Q2 2026 with quarterly forecast build through Q4 2028
B6: Prepared | C6: Claude (Anthropic) — created in claude.ai
B8: Currency / units | C8: US$ in millions unless noted
B10: Historical source | C10: SpaceX Q2 2026 earnings release (ir.spacex.com), with Q1 2026 and Q2 2025 comparatives disclosed therein
C12: SpaceX 'Reports Second Quarter 2026 Results', posted Aug 4, 2026 — https://s21.q4cdn.com/184289198/files/doc_financials/2026/q2/SpaceX-Reports-Second-Quarter-2026-Results.pdf
B14: Forecast basis | C14: Illustrative business-case projection. All forecast drivers are editable blue/yellow inputs on the Assumptions tab — this is NOT SpaceX guidance.
B16: AI compute scenario | C16: AI segment forecast is built bottom-up off a nameplate compute (GW) build-out schedule: 1.4 GW at Q2'26A, 2.2 GW at Q4'26E (consistent with management's 'more than two gigawatts' comment), 10.0 GW at Q4'27E per business-case instruction, and an illustrative continued ramp to 15.0 GW by Q4'28E.
B18: Switchable cases | C18: The Assumptions tab carries a case selector (1/2/3) governing AI capex per GW, blended revenue per GW and the marginal contract rate on new capacity. Case 1 is CoreWeave-anchored and sceptical; Case 2 reproduces management's $100B December-2026 ARR and ~1-year payback; Case 3 stresses Case 2 revenue against Nvidia's rising cost curve.
B20: Company background | C20: SpaceX completed its IPO on June 12, 2026 (Nasdaq: SPCX), raising ~$85.7B net proceeds, and issued $25B of senior notes on June 26, 2026. Q2 2026 was its first quarter reporting as a public company.
B23: Contents
B24: 1. Assumptions — forecast drivers (editable inputs), including AI compute (GW) build-out
B25: 2. KPIs — historical operating metrics (Starlink subs/ARPU, launches, AI compute)
B26: 3. Historical P&L by Segment — Space / Connectivity / AI, Q2'25, Q1'26, Q2'26, H1'25, H1'26
B27: 4. Segment Forecast Detail — quarterly build for each segment, Q3'26E-Q4'28E
B28: 5. Consolidated P&L — historical actuals + quarterly forecast through Q4 2028
B29: 6. Balance Sheet & Cash Flow — actuals at June 30, 2026 vs Dec 31, 2025
B30: 7. Dashboard — key charts
B32: Color legend:
B33: Blue = hardcoded input / actual reported figure
B34: Black = calculated formula
B35: Green = link from another sheet
B36: Yellow fill = key assumption to edit

Sheet Assumptions
A1: Forecast Assumptions
A2: Editable inputs driving Segment Forecast and Consolidated P&L. AI segment is built off a nameplate compute (GW) schedule reaching 2.2 GW at Q4'26E, 10.0 GW at Q4'27E and 15.0 GW at Q4'28E. Set the case selector below before reading any output.
A4: Driver | B4: Q3'26E | C4: Q4'26E | D4: Q1'27E | E4: Q2'27E | F4: Q3'27E | G4: Q4'27E | H4: Q1'28E | I4: Q2'28E | J4: Q3'28E | K4: Q4'28E
A5: CASE SELECTOR — type 1, 2 or 3 in the yellow cell
A6: Active case (1 / 2 / 3) | B6: 1 | C6: =CHOOSE($B$6,"CONSERVATIVE — CoreWeave-anchored","MANAGEMENT-CONSISTENT — reproduces $100B Dec-26 ARR","HIGH-CAPEX STRESS — management revenue, Nvidia cost curve") -> CONSERVATIVE — CoreWeave-anchored
A7: Case 1 CONSERVATIVE — AI economics anchored to CoreWeave's disclosed contracted rates. Produces ~$68B ARR in Dec-2026 and a ~3 year capex payback: it does NOT reproduce management's guidance, and is the sceptical benchmark.
A8: Case 2 MANAGEMENT-CONSISTENT — blended revenue per GW raised toward the level implied by the $100B ARR guidance, capex per GW raised to the ~$50B cited by Nvidia and SemiAnalysis. Reproduces both the $100B Dec-2026 ARR and a ~1 year payback on new capital.
A9: Case 3 HIGH-CAPEX STRESS — case 2 revenue, but capex per GW follows Jensen Huang's projection of $50B today rising toward $90B. Tests whether the returns survive cost inflation.
A11: CASE LIBRARY — stored inputs for each case (the active rows below pick from these)
A12: Case 1: blended revenue per GW ($mm/qtr) | B12: 2800 | C12: 2900 | D12: 2900 | E12: 2850 | F12: 2800 | G12: 2750 | H12: 2650 | I12: 2550 | J12: 2450 | K12: 2400
A13: Case 1: marginal contract rate on NEW capacity ($mm/qtr) | B13: 3200 | C13: 3300 | D13: 3300 | E13: 3200 | F13: 3150 | G13: 3100 | H13: 3000 | I13: 2900 | J13: 2800 | K13: 2700
A14: Case 1: capex per incremental GW ($mm/GW) | B14: 32000 | C14: 30000 | D14: 28000 | E14: 26500 | F14: 25000 | G14: 24000 | H14: 23000 | I14: 22000 | J14: 21500 | K14: 21000
A15: Case 2: blended revenue per GW ($mm/qtr) | B15: 6000 | C15: 6500 | D15: 6400 | E15: 6300 | F15: 6200 | G15: 6100 | H15: 5900 | I15: 5700 | J15: 5400 | K15: 5200
A16: Case 2: marginal contract rate on NEW capacity ($mm/qtr) | B16: 12000 | C16: 12000 | D16: 11800 | E16: 11500 | F16: 11200 | G16: 11000 | H16: 10500 | I16: 10000 | J16: 9500 | K16: 9000
A17: Case 2: capex per incremental GW ($mm/GW) | B17: 48000 | C17: 50000 | D17: 52000 | E17: 54000 | F17: 56000 | G17: 58000 | H17: 60000 | I17: 62000 | J17: 64000 | K17: 66000
A18: Case 3: blended revenue per GW ($mm/qtr) | B18: 6000 | C18: 6500 | D18: 6400 | E18: 6300 | F18: 6200 | G18: 6100 | H18: 5900 | I18: 5700 | J18: 5400 | K18: 5200
A19: Case 3: marginal contract rate on NEW capacity ($mm/qtr) | B19: 12000 | C19: 12000 | D19: 11800 | E19: 11500 | F19: 11200 | G19: 11000 | H19: 10500 | I19: 10000 | J19: 9500 | K19: 9000
A20: Case 3: capex per incremental GW ($mm/GW) | B20: 55000 | C20: 60000 | D20: 65000 | E20: 70000 | F20: 75000 | G20: 80000 | H20: 84000 | I20: 87000 | J20: 89000 | K20: 90000
A22: SPACE SEGMENT
A23: Revenue QoQ growth % | B23: 0.1 | C23: 0.12 | D23: 0.1 | E23: 0.09 | F23: 0.08 | G23: 0.08 | H23: 0.07 | I23: 0.07 | J23: 0.06 | K23: 0.06
A24: Cost of revenue, % of revenue | B24: 0.33 | C24: 0.32 | D24: 0.31 | E24: 0.3 | F24: 0.3 | G24: 0.29 | H24: 0.28 | I24: 0.28 | J24: 0.27 | K24: 0.27
A25: R&D, % of revenue | B25: 1 | C25: 0.9 | D25: 0.8 | E25: 0.7 | F25: 0.62 | G25: 0.55 | H25: 0.5 | I25: 0.46 | J25: 0.42 | K25: 0.39
A26: SG&A, % of revenue | B26: 0.1 | C26: 0.1 | D26: 0.09 | E26: 0.09 | F26: 0.09 | G26: 0.08 | H26: 0.08 | I26: 0.08 | J26: 0.07 | K26: 0.07
A27: Capex, % of revenue | B27: 1 | C27: 0.9 | D27: 0.75 | E27: 0.65 | F27: 0.55 | G27: 0.5 | H27: 0.45 | I27: 0.4 | J27: 0.38 | K27: 0.35
A29: CONNECTIVITY SEGMENT
A30: Net Starlink subscriber adds (millions) | B30: 1.6 | C30: 1.6 | D30: 1.5 | E30: 1.5 | F30: 1.4 | G30: 1.4 | H30: 1.3 | I30: 1.3 | J30: 1.2 | K30: 1.2
A31: Consumer ARPU ($/month) | B31: 65 | C31: 65 | D31: 64 | E31: 64 | F31: 63 | G31: 63 | H31: 62 | I31: 62 | J31: 61 | K31: 61
A32: Enterprise & Government revenue QoQ growth % | B32: 0.2 | C32: 0.18 | D32: 0.15 | E32: 0.13 | F32: 0.12 | G32: 0.11 | H32: 0.1 | I32: 0.1 | J32: 0.09 | K32: 0.09
A33: Cost of revenue, % of revenue | B33: 0.47 | C33: 0.46 | D33: 0.45 | E33: 0.44 | F33: 0.43 | G33: 0.42 | H33: 0.41 | I33: 0.41 | J33: 0.4 | K33: 0.4
A34: R&D, % of revenue | B34: 0.065 | C34: 0.062 | D34: 0.06 | E34: 0.058 | F34: 0.056 | G34: 0.055 | H34: 0.054 | I34: 0.053 | J34: 0.052 | K34: 0.051
A35: SG&A, % of revenue | B35: 0.06 | C35: 0.058 | D35: 0.056 | E35: 0.054 | F35: 0.052 | G35: 0.05 | H35: 0.049 | I35: 0.048 | J35: 0.047 | K35: 0.046
A36: Capex, % of revenue | B36: 0.3 | C36: 0.29 | D36: 0.28 | E36: 0.27 | F36: 0.26 | G36: 0.25 | H36: 0.24 | I36: 0.24 | J36: 0.23 | K36: 0.23
A38: AI SEGMENT
A39: Nameplate compute, period end (GW) | B39: 1.8 | C39: 2.2 | D39: 3 | E39: 4.5 | F39: 7 | G39: 10 | H39: 11.5 | I39: 13 | J39: 14 | K39: 15
A40: Monetizable share of compute (%) — net of internal Grok training | B40: 0.9 | C40: 0.9 | D40: 0.9 | E40: 0.9 | F40: 0.9 | G40: 0.9 | H40: 0.9 | I40: 0.9 | J40: 0.9 | K40: 0.9
A41: ACTIVE: blended revenue per GW ($mm/quarter) | B41: =CHOOSE($B$6,B12,B15,B18) -> 2800 | C41: =CHOOSE($B$6,C12,C15,C18) -> 2900 | D41: =CHOOSE($B$6,D12,D15,D18) -> 2900 | E41: =CHOOSE($B$6,E12,E15,E18) -> 2850 | F41: =CHOOSE($B$6,F12,F15,F18) -> 2800 | G41: =CHOOSE($B$6,G12,G15,G18) -> 2750 | H41: =CHOOSE($B$6,H12,H15,H18) -> 2650 | I41: =CHOOSE($B$6,I12,I15,I18) -> 2550 | ... K41: =CHOOSE($B$6,K12,K15,K18) -> 2400
A42: ACTIVE: marginal rate on new capacity ($mm/quarter) | B42: =CHOOSE($B$6,B13,B16,B19) -> 3200 | C42: =CHOOSE($B$6,C13,C16,C19) -> 3300 | D42: =CHOOSE($B$6,D13,D16,D19) -> 3300 | E42: =CHOOSE($B$6,E13,E16,E19) -> 3200 | F42: =CHOOSE($B$6,F13,F16,F19) -> 3150 | G42: =CHOOSE($B$6,G13,G16,G19) -> 3100 | H42: =CHOOSE($B$6,H13,H16,H19) -> 3000 | I42: =CHOOSE($B$6,I13,I16,I19) -> 2900 | ... K42: =CHOOSE($B$6,K13,K16,K19) -> 2700
A43: Grok subscription revenue ($mm/qtr) [ASSUMPTION - unanchored] | B43: 700 | C43: 900 | D43: 1150 | E43: 1400 | F43: 1650 | G43: 1900 | H43: 2150 | I43: 2400 | J43: 2650 | K43: 2900
A44: Cursor revenue ($mm/qtr) [ASSUMPTION - unanchored] | B44: 0 | C44: 1200 | D44: 1500 | E44: 1800 | F44: 2100 | G44: 2400 | H44: 2700 | I44: 3000 | J44: 3300 | K44: 3600
A45: Advertising revenue QoQ growth % | B45: -0.02 | C45: 0 | D45: 0.01 | E45: 0.02 | F45: 0.02 | G45: 0.02 | H45: 0.02 | I45: 0.02 | J45: 0.02 | K45: 0.02
...

Sheet KPIs
A1: Operating KPIs (Actuals)
A2: Source: SpaceX Q2 2026 earnings release, segment operating & financial data tables. Forecast compute build-out is on the Assumptions tab.
A4: Metric | B4: Q2'25A | C4: Q1'26A | D4: Q2'26A
A5: CONNECTIVITY / STARLINK
A6: Starlink subscribers (millions, period end) | B6: 6 | C6: 10.3 | D6: 12
A7: Starlink ARPU ($/month) | B7: 85 | C7: 66 | D7: 66
A9: SPACE / LAUNCH
A10: Total launches (#) | B10: 46 | C10: 40 | D10: 38
A11: Customer launches (#) | B11: 9 | C11: 7 | D11: 10
A12: Internal launches (#) | B12: 37 | C12: 33 | D12: 28
A13: Customer payloads (metric tons) | B13: 88 | C13: 45 | D13: 87
A14: Internal payloads (metric tons) | B14: 563 | C14: 511 | D14: 397
A15: Mass to orbit (metric tons) | B15: 652 | C15: 556 | D15: 485
A17: AI
A18: Nameplate compute (GW) | B18: 0.4 | C18: 1 | D18: 1.4
A21: Forward compute build-out (Q3'26E-Q4'28E) is modeled on the Assumptions tab and feeds the Segment Forecast tab.

Sheet Historical P&L
A1: Historical P&L by Segment (Actuals)
A2: $ in millions. Source: SpaceX Q2 2026 earnings release (three- and six-month tables)
A4: $mm | B4: Q2'25A | C4: Q1'26A | D4: Q2'26A | E4: H1'25A | F4: H1'26A
A5: SPACE SEGMENT
A6: Launch services revenue | B6: 490 | C6: 330 | D6: 648 | E6: 1056 | F6: 978
A7: Launch & development revenue | B7: 256 | C7: 289 | D7: 314 | E7: 555 | F7: 603
A8: Space revenue | B8: =SUM(B6:B7) -> 746 | C8: =SUM(C6:C7) -> 619 | D8: =SUM(D6:D7) -> 962 | E8: =SUM(E6:E7) -> 1611 | F8: =SUM(F6:F7) -> 1581
A9: Cost of revenue | B9: 330 | C9: 281 | D9: 329 | E9: 627 | F9: 610
A10: Research & development | B10: 693 | C10: 930 | D10: 1076 | E10: 1219 | F10: 2006
A11: Selling, general & administrative | B11: 87 | C11: 70 | D11: 99 | E11: 175 | F11: 169
A12: Impairment | B12: 5 | C12: 0 | D12: 0 | E12: 29 | F12: 0
A13: Income (loss) from operations | B13: =B8-B9-B10-B11-B12 -> -369 | C13: =C8-C9-C10-C11-C12 -> -662 | D13: =D8-D9-D10-D11-D12 -> -542 | E13: =E8-E9-E10-E11-E12 -> -439 | F13: =F8-F9-F10-F11-F12 -> -1204
A14: Adjusted EBITDA | B14: -93 | C14: -351 | D14: -205 | E14: 131 | F14: -556
A15: Capex | B15: 946 | C15: 1052 | D15: 1174 | E15: 1705 | F15: 2226
A17: CONNECTIVITY SEGMENT
A18: Consumer revenue | B18: 1721 | C18: 2148 | D18: 2485 | E18: 3213 | F18: 4633
A19: Enterprise & government revenue | B19: 867 | C19: 1109 | D19: 1806 | E19: 1849 | F19: 2915
A20: Connectivity revenue | B20: =SUM(B18:B19) -> 2588 | C20: =SUM(C18:C19) -> 3257 | D20: =SUM(D18:D19) -> 4291 | E20: =SUM(E18:E19) -> 5062 | F20: =SUM(F18:F19) -> 7548
A21: Cost of revenue | B21: 1401 | C21: 1651 | D21: 2060 | E21: 2615 | F21: 3711
A22: Research & development | B22: 143 | C22: 205 | D22: 294 | E22: 266 | F22: 499
A23: Selling, general & administrative | B23: 121 | C23: 213 | D23: 281 | E23: 225 | F23: 494
A24: Income from operations | B24: =B20-B21-B22-B23 -> 923 | C24: =C20-C21-C22-C23 -> 1188 | D24: =D20-D21-D22-D23 -> 1656 | E24: =E20-E21-E22-E23 -> 1956 | F24: =F20-F21-F22-F23 -> 2844
A25: Adjusted EBITDA | B25: 1583 | C25: 2087 | D25: 2597 | E25: 3200 | F25: 4684
A26: Capex | B26: 1130 | C26: 1332 | D26: 1367 | E26: 1944 | F26: 2699
A28: AI SEGMENT
A29: Advertising revenue | B29: 426 | C29: 343 | D29: 367 | E29: 870 | F29: 710
A30: AI solutions & infrastructure revenue | B30: 311 | C30: 475 | D30: 2194 | E30: 595 | F30: 2669
A31: AI revenue | B31: =SUM(B29:B30) -> 737 | C31: =SUM(C29:C30) -> 818 | D31: =SUM(D29:D30) -> 2561 | E31: =SUM(E29:E30) -> 1465 | F31: =SUM(F29:F30) -> 3379
A32: Cost of revenue | B32: 551 | C32: 456 | D32: 1106 | E32: 1002 | F32: 1562
A33: Research & development | B33: 1122 | C33: 2379 | D33: 2178 | E33: 2030 | F33: 4557
A34: Selling, general & administrative | B34: 398 | C34: 463 | D34: 532 | E34: 699 | F34: 995
A35: Restructuring charges (credits) | B35: 190 | C35: -11 | D35: 2 | E35: 194 | F35: -9
A36: Loss from operations | B36: =B31-B32-B33-B34-B35 -> -1524 | C36: =C31-C32-C33-C34-C35 -> -2469 | D36: =D31-D32-D33-D34-D35 -> -1257 | E36: =E31-E32-E33-E34-E35 -> -2460 | F36: =F31-F32-F33-F34-F35 -> -3726
A37: Adjusted EBITDA | B37: -276 | C37: -609 | D37: 1146 | E37: -387 | F37: 537
A38: Capex | B38: 749 | C38: 7723 | D38: 15828 | E38: 3316 | F38: 23551
A40: TOTAL COMPANY (CHECK)
A41: Total revenue | B41: =B8+B20+B31 -> 4071 | C41: =C8+C20+C31 -> 4694 | D41: =D8+D20+D31 -> 7814 | E41: =E8+E20+E31 -> 8138 | F41: =F8+F20+F31 -> 12508
A42: Total income (loss) from operations | B42: =B13+B24+B36 -> -970 | C42: =C13+C24+C36 -> -1943 | D42: =D13+D24+D36 -> -143 | E42: =E13+E24+E36 -> -943 | F42: =F13+F24+F36 -> -2086

Sheet Segment Forecast
A1: Segment Forecast Detail (Illustrative Business Case)
A2: $ in millions unless noted. Q2'26A = actual jump-off quarter. Q3'26E-Q4'28E driven by Assumptions tab. AI revenue = (revenue-generating GW x blended $/GW/quarter) + Grok subscriptions + Cursor + Advertising.
A4: $mm | B4: Q2'26A | C4: Q3'26E | D4: Q4'26E | E4: Q1'27E | F4: Q2'27E | G4: Q3'27E | H4: Q4'27E | I4: Q1'28E | J4: Q2'28E | K4: Q3'28E | L4: Q4'28E
A5: SPACE SEGMENT
A6: Revenue | B6: ='Historical P&L'!D8 -> 962 | C6: =B6*(1+Assumptions!B23) -> 1058.2 | D6: =C6*(1+Assumptions!C23) -> 1185.184 | E6: =D6*(1+Assumptions!D23) -> 1303.7024 | F6: =E6*(1+Assumptions!E23) -> 1421.0356 | G6: =F6*(1+Assumptions!F23) -> 1534.7185 | H6: =G6*(1+Assumptions!G23) -> 1657.4959 | I6: =H6*(1+Assumptions!H23) -> 1773.5207 | J6: =I6*(1+Assumptions!I23) -> 1897.6671 | ... L6: =K6*(1+Assumptions!K23) -> 2132.2188
A7: QoQ growth % | C7: =Assumptions!B23 -> 0.1 | D7: =Assumptions!C23 -> 0.12 | E7: =Assumptions!D23 -> 0.1 | F7: =Assumptions!E23 -> 0.09 | G7: =Assumptions!F23 -> 0.08 | H7: =Assumptions!G23 -> 0.08 | I7: =Assumptions!H23 -> 0.07 | J7: =Assumptions!I23 -> 0.07 | ... L7: =Assumptions!K23 -> 0.06
A8: Cost of revenue | C8: =C6*Assumptions!B24 -> 349.206 | D8: =D6*Assumptions!C24 -> 379.25888 | E8: =E6*Assumptions!D24 -> 404.14774 | F8: =F6*Assumptions!E24 -> 426.31068 | G8: =G6*Assumptions!F24 -> 460.41554 | H8: =H6*Assumptions!G24 -> 480.67382 | I8: =I6*Assumptions!H24 -> 496.58578 | J8: =J6*Assumptions!I24 -> 531.34679 | ... L8: =L6*Assumptions!K24 -> 575.69906
A9: Research & development | C9: =C6*Assumptions!B25 -> 1058.2 | D9: =D6*Assumptions!C25 -> 1066.6656 | E9: =E6*Assumptions!D25 -> 1042.9619 | F9: =F6*Assumptions!E25 -> 994.72493 | G9: =G6*Assumptions!F25 -> 951.52545 | H9: =H6*Assumptions!G25 -> 911.62277 | I9: =I6*Assumptions!H25 -> 886.76033 | J9: =J6*Assumptions!I25 -> 872.92687 | ... L9: =L6*Assumptions!K25 -> 831.56532
A10: Selling, general & administrative | C10: =C6*Assumptions!B26 -> 105.82 | D10: =D6*Assumptions!C26 -> 118.5184 | E10: =E6*Assumptions!D26 -> 117.33322 | F10: =F6*Assumptions!E26 -> 127.89321 | G10: =G6*Assumptions!F26 -> 138.12466 | H10: =H6*Assumptions!G26 -> 132.59968 | I10: =I6*Assumptions!H26 -> 141.88165 | J10: =J6*Assumptions!I26 -> 151.81337 | ... L10: =L6*Assumptions!K26 -> 149.25531
A11: Income (loss) from operations | B11: ='Historical P&L'!D13 -> -542 | C11: =C6-C8-C9-C10 -> -455.026 | D11: =D6-D8-D9-D10 -> -379.25888 | E11: =E6-E8-E9-E10 -> -260.74048 | F11: =F6-F8-F9-F10 -> -127.89321 | G11: =G6-G8-G9-G10 -> -15.347185 | H11: =H6-H8-H9-H10 -> 132.59968 | I11: =I6-I8-I9-I10 -> 248.29289 | J11: =J6-J8-J9-J10 -> 341.58008 | ... L11: =L6-L8-L9-L10 -> 575.69906
A12: Capex | B12: ='Historical P&L'!D15 -> 1174 | C12: =C6*Assumptions!B27 -> 1058.2 | D12: =D6*Assumptions!C27 -> 1066.6656 | E12: =E6*Assumptions!D27 -> 977.7768 | F12: =F6*Assumptions!E27 -> 923.67315 | G12: =G6*Assumptions!F27 -> 844.09516 | H12: =H6*Assumptions!G27 -> 828.74797 | I12: =I6*Assumptions!H27 -> 798.0843 | J12: =J6*Assumptions!I27 -> 759.06684 | ... L12: =L6*Assumptions!K27 -> 746.27657
A14: CONNECTIVITY SEGMENT
A15: Starlink subscribers, period end (mm) | B15: 12 | C15: =B15+Assumptions!B30 -> 13.6 | D15: =C15+Assumptions!C30 -> 15.2 | E15: =D15+Assumptions!D30 -> 16.7 | F15: =E15+Assumptions!E30 -> 18.2 | G15: =F15+Assumptions!F30 -> 19.6 | H15: =G15+Assumptions!G30 -> 21 | I15: =H15+Assumptions!H30 -> 22.3 | J15: =I15+Assumptions!I30 -> 23.6 | ... L15: =K15+Assumptions!K30 -> 26
A16: Consumer ARPU ($/month) | B16: 66 | C16: =Assumptions!B31 -> 65 | D16: =Assumptions!C31 -> 65 | E16: =Assumptions!D31 -> 64 | F16: =Assumptions!E31 -> 64 | G16: =Assumptions!F31 -> 63 | H16: =Assumptions!G31 -> 63 | I16: =Assumptions!H31 -> 62 | J16: =Assumptions!I31 -> 62 | ... L16: =Assumptions!K31 -> 61
A17: Consumer revenue (subs x ARPU x 3 months) | B17: ='Historical P&L'!D18 -> 2485 | C17: =C15*C16*3 -> 2652 | D17: =D15*D16*3 -> 2964 | E17: =E15*E16*3 -> 3206.4 | F17: =F15*F16*3 -> 3494.4 | G17: =G15*G16*3 -> 3704.4 | H17: =H15*H16*3 -> 3969 | I17: =I15*I16*3 -> 4147.8 | J17: =J15*J16*3 -> 4389.6 | ... L17: =L15*L16*3 -> 4758
A18: Enterprise & government revenue | B18: ='Historical P&L'!D19 -> 1806 | C18: =B18*(1+Assumptions!B32) -> 2167.2 | D18: =C18*(1+Assumptions!C32) -> 2557.296 | E18: =D18*(1+Assumptions!D32) -> 2940.8904 | F18: =E18*(1+Assumptions!E32) -> 3323.2062 | G18: =F18*(1+Assumptions!F32) -> 3721.9909 | H18: =G18*(1+Assumptions!G32) -> 4131.4099 | I18: =H18*(1+Assumptions!H32) -> 4544.5509 | J18: =I18*(1+Assumptions!I32) -> 4999.006 | ... L18: =K18*(1+Assumptions!K32) -> 5939.319
A19: Connectivity revenue | B19: ='Historical P&L'!D20 -> 4291 | C19: =C17+C18 -> 4819.2 | D19: =D17+D18 -> 5521.296 | E19: =E17+E18 -> 6147.2904 | F19: =F17+F18 -> 6817.6062 | G19: =G17+G18 -> 7426.3909 | H19: =H17+H18 -> 8100.4099 | I19: =I17+I18 -> 8692.3509 | J19: =J17+J18 -> 9388.606 | ... L19: =L17+L18 -> 10697.319
A20: Cost of revenue | C20: =C19*Assumptions!B33 -> 2265.024 | D20: =D19*Assumptions!C33 -> 2539.7962 | E20: =E19*Assumptions!D33 -> 2766.2807 | F20: =F19*Assumptions!E33 -> 2999.7467 | G20: =G19*Assumptions!F33 -> 3193.3481 | H20: =H19*Assumptions!G33 -> 3402.1722 | I20: =I19*Assumptions!H33 -> 3563.8639 | J20: =J19*Assumptions!I33 -> 3849.3284 | ... L20: =L19*Assumptions!K33 -> 4278.9276
A21: Research & development | C21: =C19*Assumptions!B34 -> 313.248 | D21: =D19*Assumptions!C34 -> 342.32035 | E21: =E19*Assumptions!D34 -> 368.83742 | F21: =F19*Assumptions!E34 -> 395.42116 | G21: =G19*Assumptions!F34 -> 415.87789 | H21: =H19*Assumptions!G34 -> 445.52254 | I21: =I19*Assumptions!H34 -> 469.38695 | J21: =J19*Assumptions!I34 -> 497.59612 | ... L21: =L19*Assumptions!K34 -> 545.56327
A22: Selling, general & administrative | C22: =C19*Assumptions!B35 -> 289.152 | D22: =D19*Assumptions!C35 -> 320.23517 | E22: =E19*Assumptions!D35 -> 344.24826 | F22: =F19*Assumptions!E35 -> 368.15073 | G22: =G19*Assumptions!F35 -> 386.17233 | H22: =H19*Assumptions!G35 -> 405.02049 | I22: =I19*Assumptions!H35 -> 425.92519 | J22: =J19*Assumptions!I35 -> 450.65309 | ... L22: =L19*Assumptions!K35 -> 492.07667
A23: Income from operations | B23: ='Historical P&L'!D24 -> 1656 | C23: =C19-C20-C21-C22 -> 1951.776 | D23: =D19-D20-D21-D22 -> 2318.9443 | E23: =E19-E20-E21-E22 -> 2667.924 | F23: =F19-F20-F21-F22 -> 3054.2876 | G23: =G19-G20-G21-G22 -> 3430.9926 | H23: =H19-H20-H21-H22 -> 3847.6947 | I23: =I19-I20-I21-I22 -> 4233.1749 | J23: =J19-J20-J21-J22 -> 4591.0283 | ... L23: =L19-L20-L21-L22 -> 5380.7515
A24: Capex | B24: ='Historical P&L'!D26 -> 1367 | C24: =C19*Assumptions!B36 -> 1445.76 | D24: =D19*Assumptions!C36 -> 1601.1758 | E24: =E19*Assumptions!D36 -> 1721.2413 | F24: =F19*Assumptions!E36 -> 1840.7537 | G24: =G19*Assumptions!F36 -> 1930.8616 | H24: =H19*Assumptions!G36 -> 2025.1025 | I24: =I19*Assumptions!H36 -> 2086.1642 | J24: =J19*Assumptions!I36 -> 2253.2654 | ... L24: =L19*Assumptions!K36 -> 2460.3834
A26: AI SEGMENT
A27: Nameplate compute, period end (GW) | B27: 1.4 | C27: =Assumptions!B39 -> 1.8 | D27: =Assumptions!C39 -> 2.2 | E27: =Assumptions!D39 -> 3 | F27: =Assumptions!E39 -> 4.5 | G27: =Assumptions!F39 -> 7 | H27: =Assumptions!G39 -> 10 | I27: =Assumptions!H39 -> 11.5 | J27: =Assumptions!I39 -> 13 | ... L27: =Assumptions!K39 -> 15
A28: Monetizable share (net of internal Grok training) | B28: 1 | C28: =Assumptions!B40 -> 0.9 | D28: =Assumptions!C40 -> 0.9 | E28: =Assumptions!D40 -> 0.9 | F28: =Assumptions!E40 -> 0.9 | G28: =Assumptions!F40 -> 0.9 | H28: =Assumptions!G40 -> 0.9 | I28: =Assumptions!H40 -> 0.9 | J28: =Assumptions!I40 -> 0.9 | ... L28: =Assumptions!K40 -> 0.9
A29: Revenue-generating compute (GW) | B29: =B27*B28 -> 1.4 | C29: =C27*C28 -> 1.62 | D29: =D27*D28 -> 1.98 | E29: =E27*E28 -> 2.7 | F29: =F27*F28 -> 4.05 | G29: =G27*G28 -> 6.3 | H29: =H27*H28 -> 9 | I29: =I27*I28 -> 10.35 | ... L29: =L27*L28 -> 13.5
A30: AI infrastructure revenue per revenue-generating GW ($mm/qtr) | B30: ='Historical P&L'!D30/B27 -> 1567.1429 | C30: =Assumptions!B41 -> 2800 | D30: =Assumptions!C41 -> 2900 | E30: =Assumptions!D41 -> 2900 | F30: =Assumptions!E41 -> 2850 | G30: =Assumptions!F41 -> 2800 | H30: =Assumptions!G41 -> 2750 | I30: =Assumptions!H41 -> 2650 | J30: =Assumptions!I41 -> 2550 | ... L30: =Assumptions!K41 -> 2400
A31: AI infrastructure revenue (revenue-generating GW x $/GW/qtr) | B31: ='Historical P&L'!D30 -> 2194 | C31: =C29*C30 -> 4536 | D31: =D29*D30 -> 5742 | E31: =E29*E30 -> 7830 | F31: =F29*F30 -> 11542.5 | G31: =G29*G30 -> 17640 | H31: =H29*H30 -> 24750 | I31: =I29*I30 -> 27427.5 | J31: =J29*J30 -> 29835 | ... L31: =L29*L30 -> 32400
A32: Grok subscription revenue [ASSUMPTION — no historical anchor] | B32: 0 | C32: =Assumptions!B43 -> 700 | D32: =Assumptions!C43 -> 900 | E32: =Assumptions!D43 -> 1150 | F32: =Assumptions!E43 -> 1400 | G32: =Assumptions!F43 -> 1650 | H32: =Assumptions!G43 -> 1900 | I32: =Assumptions!H43 -> 2150 | J32: =Assumptions!I43 -> 2400 | ... L32: =Assumptions!K43 -> 2900
A33: Cursor revenue [ASSUMPTION — no historical anchor] | B33: 0 | C33: =Assumptions!B44 -> 0 | D33: =Assumptions!C44 -> 1200 | E33: =Assumptions!D44 -> 1500 | F33: =Assumptions!E44 -> 1800 | G33: =Assumptions!F44 -> 2100 | H33: =Assumptions!G44 -> 2400 | I33: =Assumptions!H44 -> 2700 | J33: =Assumptions!I44 -> 3000 | ... L33: =Assumptions!K44 -> 3600
A34: Advertising revenue | B34: ='Historical P&L'!D29 -> 367 | C34: =B34*(1+Assumptions!B45) -> 359.66 | D34: =C34*(1+Assumptions!C45) -> 359.66 | E34: =D34*(1+Assumptions!D45) -> 363.2566 | F34: =E34*(1+Assumptions!E45) -> 370.52173 | G34: =F34*(1+Assumptions!F45) -> 377.93217 | H34: =G34*(1+Assumptions!G45) -> 385.49081 | I34: =H34*(1+Assumptions!H45) -> 393.20063 | J34: =I34*(1+Assumptions!I45) -> 401.06464 | ... L34: =K34*(1+Assumptions!K45) -> 417.26765
A35: AI revenue | B35: ='Historical P&L'!D31 -> 2561 | C35: =C31+C32+C33+C34 -> 5595.66 | D35: =D31+D32+D33+D34 -> 8201.66 | E35: =E31+E32+E33+E34 -> 10843.257 | F35: =F31+F32+F33+F34 -> 15113.022 | G35: =G31+G32+G33+G34 -> 21767.932 | H35: =H31+H32+H33+H34 -> 29435.491 | I35: =I31+I32+I33+I34 -> 32670.701 | J35: =J31+J32+J33+J34 -> 35636.065 | ... L35: =L31+L32+L33+L34 -> 39317.268
A36: QoQ growth % | C36: =IFERROR(C35/B35-1,"n/a") -> 1.1849512 | D36: =IFERROR(D35/C35-1,"n/a") -> 0.46571807 | E36: =IFERROR(E35/D35-1,"n/a") -> 0.32208073 | F36: =IFERROR(F35/E35-1,"n/a") -> 0.39377147 | G36: =IFERROR(G35/F35-1,"n/a") -> 0.44034281 | H36: =IFERROR(H35/G35-1,"n/a") -> 0.35224102 | I36: =IFERROR(I35/H35-1,"n/a") -> 0.10990847 | J36: =IFERROR(J35/I35-1,"n/a") -> 0.090765241 | ... L36: =IFERROR(L35/K35-1,"n/a") -> 0.056090061
A37: Cost of revenue | C37: =C35*Assumptions!B46 -> 2238.264 | D37: =D35*Assumptions!C46 -> 3198.6474 | E37: =E35*Assumptions!D46 -> 4120.4375 | F37: =F35*Assumptions!E46 -> 5591.818 | G37: =G35*Assumptions!F46 -> 7836.4556 | H37: =H35*Assumptions!G46 -> 10302.422 | I37: =I35*Assumptions!H46 -> 11108.038 | J37: =J35*Assumptions!I46 -> 12116.262 | ... L37: =L35*Assumptions!K46 -> 12974.698
A38: Research & development | C38: =C35*Assumptions!B47 -> 4196.745 | D38: =D35*Assumptions!C47 -> 5331.079 | E38: =E35*Assumptions!D47 -> 6289.0888 | F38: =F35*Assumptions!E47 -> 7858.7713 | G38: =G35*Assumptions!F47 -> 10230.928 | H38: =H35*Assumptions!G47 -> 12657.261 | I38: =I35*Assumptions!H47 -> 13068.28 | J38: =J35*Assumptions!I47 -> 13185.344 | ... L38: =L35*Assumptions!K47 -> 12974.698
A39: Selling, general & administrative | C39: =C35*Assumptions!B48 -> 1007.2188 | D39: =D35*Assumptions!C48 -> 1312.2656 | E39: =E35*Assumptions!D48 -> 1626.4885 | F39: =F35*Assumptions!E48 -> 2115.823 | G39: =G35*Assumptions!F48 -> 2829.8312 | H39: =H35*Assumptions!G48 -> 3532.2589 | I39: =I35*Assumptions!H48 -> 3593.7771 | J39: =J35*Assumptions!I48 -> 3919.9671 | ... L39: =L35*Assumptions!K48 -> 3931.7268
A40: Income (loss) from operations | B40: ='Historical P&L'!D36 -> -1257 | C40: =C35-C37-C38-C39 -> -1846.5678 | D40: =D35-D37-D38-D39 -> -1640.332 | E40: =E35-E37-E38-E39 -> -1192.7582 | F40: =F35-F37-F38-F39 -> -453.39065 | G40: =G35-G37-G38-G39 -> 870.71729 | H40: =H35-H37-H38-H39 -> 2943.5491 | I40: =I35-I37-I38-I39 -> 4900.6051 | J40: =J35-J37-J38-J39 -> 6414.4916 | ... L40: =L35-L37-L38-L39 -> 9436.1442
A41: Incremental GW added in quarter | B41: 0.4 | C41: =C27-B27 -> 0.4 | D41: =D27-C27 -> 0.4 | E41: =E27-D27 -> 0.8 | F41: =F27-E27 -> 1.5 | G41: =G27-F27 -> 2.5 | H41: =H27-G27 -> 3 | I41: =I27-H27 -> 1.5 | J41: =J27-I27 -> 1.5 | ... L41: =L27-K27 -> 1
A42: Capex per incremental GW ($mm/GW) | B42: ='Historical P&L'!D38/B41 -> 39570 | C42: =Assumptions!B49 -> 32000 | D42: =Assumptions!C49 -> 30000 | E42: =Assumptions!D49 -> 28000 | F42: =Assumptions!E49 -> 26500 | G42: =Assumptions!F49 -> 25000 | H42: =Assumptions!G49 -> 24000 | I42: =Assumptions!H49 -> 23000 | J42: =Assumptions!I49 -> 22000 | ... L42: =Assumptions!K49 -> 21000
A43: Marginal contract rate on new capacity ($mm/GW/qtr) | C43: =Assumptions!B42 -> 3200 | D43: =Assumptions!C42 -> 3300 | E43: =Assumptions!D42 -> 3300 | F43: =Assumptions!E42 -> 3200 | G43: =Assumptions!F42 -> 3150 | H43: =Assumptions!G42 -> 3100 | I43: =Assumptions!H42 -> 3000 | J43: =Assumptions!I42 -> 2900 | ... L43: =Assumptions!K42 -> 2700
...

Sheet Consolidated P&L
A1: Consolidated P&L — Actuals & Forecast
A2: $ in millions. Historical columns link to Historical P&L; forecast columns link to Segment Forecast + Assumptions, through Q4 2028
A4: $mm | B4: Q2'25A | C4: Q1'26A | D4: Q2'26A | E4: Q3'26E | F4: Q4'26E | G4: Q1'27E | H4: Q2'27E | I4: Q3'27E | J4: Q4'27E | K4: Q1'28E | L4: Q2'28E | M4: Q3'28E | N4: Q4'28E
A5: REVENUE BY SEGMENT
A6: Space | B6: ='Historical P&L'!B8 -> 746 | C6: ='Historical P&L'!C8 -> 619 | D6: ='Segment Forecast'!B6 -> 962 | E6: ='Segment Forecast'!C6 -> 1058.2 | F6: ='Segment Forecast'!D6 -> 1185.184 | G6: ='Segment Forecast'!E6 -> 1303.7024 | H6: ='Segment Forecast'!F6 -> 1421.0356 | I6: ='Segment Forecast'!G6 -> 1534.7185 | J6: ='Segment Forecast'!H6 -> 1657.4959 | K6: ='Segment Forecast'!I6 -> 1773.5207 | ... N6: ='Segment Forecast'!L6 -> 2132.2188
A7: Connectivity | B7: ='Historical P&L'!B20 -> 2588 | C7: ='Historical P&L'!C20 -> 3257 | D7: ='Segment Forecast'!B19 -> 4291 | E7: ='Segment Forecast'!C19 -> 4819.2 | F7: ='Segment Forecast'!D19 -> 5521.296 | G7: ='Segment Forecast'!E19 -> 6147.2904 | H7: ='Segment Forecast'!F19 -> 6817.6062 | I7: ='Segment Forecast'!G19 -> 7426.3909 | J7: ='Segment Forecast'!H19 -> 8100.4099 | K7: ='Segment Forecast'!I19 -> 8692.3509 | ... N7: ='Segment Forecast'!L19 -> 10697.319
A8: AI | B8: ='Historical P&L'!B31 -> 737 | C8: ='Historical P&L'!C31 -> 818 | D8: ='Segment Forecast'!B35 -> 2561 | E8: ='Segment Forecast'!C35 -> 5595.66 | F8: ='Segment Forecast'!D35 -> 8201.66 | G8: ='Segment Forecast'!E35 -> 10843.257 | H8: ='Segment Forecast'!F35 -> 15113.022 | I8: ='Segment Forecast'!G35 -> 21767.932 | J8: ='Segment Forecast'!H35 -> 29435.491 | K8: ='Segment Forecast'!I35 -> 32670.701 | ... N8: ='Segment Forecast'!L35 -> 39317.268
A9: Total revenue | B9: =SUM(B6:B8) -> 4071 | C9: =SUM(C6:C8) -> 4694 | D9: =SUM(D6:D8) -> 7814 | E9: =SUM(E6:E8) -> 11473.06 | F9: =SUM(F6:F8) -> 14908.14 | G9: =SUM(G6:G8) -> 18294.249 | H9: =SUM(H6:H8) -> 23351.663 | I9: =SUM(I6:I8) -> 30729.042 | ... N9: =SUM(N6:N8) -> 52146.805
A10: YoY growth % | F10: =IFERROR(F9/B9-1,"n/a") -> 2.6620339 | G10: =IFERROR(G9/C9-1,"n/a") -> 2.8973689 | H10: =IFERROR(H9/D9-1,"n/a") -> 1.9884391 | I10: =IFERROR(I9/E9-1,"n/a") -> 1.6783649 | J10: =IFERROR(J9/F9-1,"n/a") -> 1.6289931 | K10: =IFERROR(K9/G9-1,"n/a") -> 1.3579307 | L10: =IFERROR(L9/H9-1,"n/a") -> 1.0093788 | M10: =IFERROR(M9/I9-1,"n/a") -> 0.60200016 | N10: =IFERROR(N9/J9-1,"n/a") -> 0.33049977
A12: REVENUE RUN-RATE — MANAGEMENT'S ARR BASIS (exit month x 12)
A13: Exit-month revenue (final month of quarter) | E13: =E9*Assumptions!$B$67 -> 4359.7628 | F13: =F9*Assumptions!$B$67 -> 5665.0932 | G13: =G9*Assumptions!$B$67 -> 6951.8148 | H13: =H9*Assumptions!$B$67 -> 8873.6321 | I13: =I9*Assumptions!$B$67 -> 11677.036 | J13: =J9*Assumptions!$B$67 -> 14893.491 | K13: =K9*Assumptions!$B$67 -> 16391.897 | L13: =L9*Assumptions!$B$67 -> 17830.488 | ... N13: =N9*Assumptions!$B$67 -> 19815.786
A14: ARR (exit month x 12) | E14: =E13*12 -> 52317.154 | F14: =F13*12 -> 67981.118 | G14: =G13*12 -> 83421.777 | H14: =H13*12 -> 106483.59 | I14: =I13*12 -> 140124.43 | J14: =J13*12 -> 178721.89 | K14: =K13*12 -> 196702.77 | L14: =L13*12 -> 213965.86 | ... N14: =N13*12 -> 237789.43
A15: Gap to management's $100B December 2026 guidance | F15: =F14-100000 -> -32018.882
A16: Management measures ARR as expected December revenue annualised, not the quarter multiplied by four, and states it inclusive of Cursor. This block puts the model on that same basis so the comparison is like-for-like. The exit-month share is an input on the Assumptions tab.
A18: COSTS & EXPENSES
A19: Cost of revenue | B19: =2282 -> 2282 | C19: ='Historical P&L'!C9+'Historical P&L'!C21+'Historical P&L'!C32 -> 2388 | D19: ='Historical P&L'!D9+'Historical P&L'!D21+'Historical P&L'!D32 -> 3495 | E19: ='Segment Forecast'!C8+'Segment Forecast'!C20+'Segment Forecast'!C37 -> 4852.494 | F19: ='Segment Forecast'!D8+'Segment Forecast'!D20+'Segment Forecast'!D37 -> 6117.7024 | G19: ='Segment Forecast'!E8+'Segment Forecast'!E20+'Segment Forecast'!E37 -> 7290.8659 | H19: ='Segment Forecast'!F8+'Segment Forecast'!F20+'Segment Forecast'!F37 -> 9017.8754 | I19: ='Segment Forecast'!G8+'Segment Forecast'!G20+'Segment Forecast'!G37 -> 11490.219 | J19: ='Segment Forecast'!H8+'Segment Forecast'!H20+'Segment Forecast'!H37 -> 14185.268 | K19: ='Segment Forecast'!I8+'Segment Forecast'!I20+'Segment Forecast'!I37 -> 15168.488 | L19: ='Segment Forecast'!J8+'Segment Forecast'!J20+'Segment Forecast'!J37 -> 16496.937 | ... N19: ='Segment Forecast'!L8+'Segment Forecast'!L20+'Segment Forecast'!L37 -> 17829.325
A20: Research & development | B20: =1958 -> 1958 | C20: ='Historical P&L'!C10+'Historical P&L'!C22+'Historical P&L'!C33 -> 3514 | D20: ='Historical P&L'!D10+'Historical P&L'!D22+'Historical P&L'!D33 -> 3548 | E20: ='Segment Forecast'!C9+'Segment Forecast'!C21+'Segment Forecast'!C38 -> 5568.193 | F20: ='Segment Forecast'!D9+'Segment Forecast'!D21+'Segment Forecast'!D38 -> 6740.065 | G20: ='Segment Forecast'!E9+'Segment Forecast'!E21+'Segment Forecast'!E38 -> 7700.8882 | H20: ='Segment Forecast'!F9+'Segment Forecast'!F21+'Segment Forecast'!F38 -> 9248.9174 | I20: ='Segment Forecast'!G9+'Segment Forecast'!G21+'Segment Forecast'!G38 -> 11598.331 | J20: ='Segment Forecast'!H9+'Segment Forecast'!H21+'Segment Forecast'!H38 -> 14014.406 | K20: ='Segment Forecast'!I9+'Segment Forecast'!I21+'Segment Forecast'!I38 -> 14424.428 | L20: ='Segment Forecast'!J9+'Segment Forecast'!J21+'Segment Forecast'!J38 -> 14555.867 | ... N20: ='Segment Forecast'!L9+'Segment Forecast'!L21+'Segment Forecast'!L38 -> 14351.827
A21: Selling, general & administrative | B21: =606 -> 606 | C21: ='Historical P&L'!C11+'Historical P&L'!C23+'Historical P&L'!C34 -> 746 | D21: ='Historical P&L'!D11+'Historical P&L'!D23+'Historical P&L'!D34 -> 912 | E21: ='Segment Forecast'!C10+'Segment Forecast'!C22+'Segment Forecast'!C39 -> 1402.1908 | F21: ='Segment Forecast'!D10+'Segment Forecast'!D22+'Segment Forecast'!D39 -> 1751.0192 | G21: ='Segment Forecast'!E10+'Segment Forecast'!E22+'Segment Forecast'!E39 -> 2088.07 | H21: ='Segment Forecast'!F10+'Segment Forecast'!F22+'Segment Forecast'!F39 -> 2611.867 | I21: ='Segment Forecast'!G10+'Segment Forecast'!G22+'Segment Forecast'!G39 -> 3354.1282 | J21: ='Segment Forecast'!H10+'Segment Forecast'!H22+'Segment Forecast'!H39 -> 4069.8791 | K21: ='Segment Forecast'!I10+'Segment Forecast'!I22+'Segment Forecast'!I39 -> 4161.5839 | L21: ='Segment Forecast'!J10+'Segment Forecast'!J22+'Segment Forecast'!J39 -> 4522.4336 | ... N21: ='Segment Forecast'!L10+'Segment Forecast'!L22+'Segment Forecast'!L39 -> 4573.0588
A22: Restructuring charges (credits) | B22: 190 | C22: -11 | D22: 2 | E22: 0 | F22: 0 | G22: 0 | H22: 0 | I22: 0 | J22: 0 | K22: 0 | L22: 0 | M22: 0 | N22: 0
A23: Impairment | B23: 5 | C23: 0 | D23: 0 | E23: 0 | F23: 0 | G23: 0 | H23: 0 | I23: 0 | J23: 0 | K23: 0 | L23: 0 | M23: 0 | N23: 0
A24: Total costs and expenses (excl. new-capex D&A) | B24: =SUM(B19:B23) -> 5041 | C24: =SUM(C19:C23) -> 6637 | D24: =SUM(D19:D23) -> 7957 | E24: =SUM(E19:E23) -> 11822.878 | F24: =SUM(F19:F23) -> 14608.787 | G24: =SUM(G19:G23) -> 17079.824 | H24: =SUM(H19:H23) -> 20878.66 | I24: =SUM(I19:I23) -> 26442.679 | ... N24: =SUM(N19:N23) -> 36754.211
A25: Operating income (loss) before new-capex D&A | B25: =B9-B24 -> -970 | C25: =C9-C24 -> -1943 | D25: =D9-D24 -> -143 | E25: =E9-E24 -> -349.8178 | F25: =F9-F24 -> 299.35344 | G25: =G9-G24 -> 1214.4253 | H25: =H9-H24 -> 2473.0037 | I25: =I9-I24 -> 4286.3627 | ... N25: =N9-N24 -> 15392.595
A26: Depreciation on new forecast-period capex | B26: 0 | C26: 0 | D26: 0 | E26: ='Financing & D&A'!B8 -> 0 | F26: ='Financing & D&A'!C8 -> 0 | G26: ='Financing & D&A'!D8 -> 617.6241 | H26: ='Financing & D&A'!E8 -> 1209.5763 | I26: ='Financing & D&A'!F8 -> 2222.5009 | J26: ='Financing & D&A'!G8 -> 3938.2617 | K26: ='Financing & D&A'!H8 -> 6572.5725 | L26: ='Financing & D&A'!I8 -> 9593.46 | ... N26: ='Financing & D&A'!K8 -> 12555.536
A27: Historical columns show zero because depreciation on assets already in service at Q2'26 is embedded in the reported cost lines above (and in the cost ratios used to forecast them). Only depreciation on NEW capex spent during the forecast is added here, to avoid double-counting.
A28: Total costs and expenses | B28: =B24+B26 -> 5041 | C28: =C24+C26 -> 6637 | D28: =D24+D26 -> 7957 | E28: =E24+E26 -> 11822.878 | F28: =F24+F26 -> 14608.787 | G28: =G24+G26 -> 17697.448 | H28: =H24+H26 -> 22088.236 | I28: =I24+I26 -> 28665.18 | ... N28: =N24+N26 -> 49309.747
A29: Income (loss) from operations | B29: =B9-B28 -> -970 | C29: =C9-C28 -> -1943 | D29: =D9-D28 -> -143 | E29: =E9-E28 -> -349.8178 | F29: =F9-F28 -> 299.35344 | G29: =G9-G28 -> 596.80123 | H29: =H9-H28 -> 1263.4274 | I29: =I9-I28 -> 2063.8618 | ... N29: =N9-N28 -> 2837.0584
A30: Operating margin % | B30: =B29/B9 -> -0.2382707 | C30: =C29/C9 -> -0.41393268 | D30: =D29/D9 -> -0.018300486 | E30: =E29/E9 -> -0.030490366 | F30: =F29/F9 -> 0.020079865 | G30: =G29/G9 -> 0.03262234 | H30: =H29/H9 -> 0.054104386 | I30: =I29/I9 -> 0.067163233 | ... N30: =N29/N9 -> 0.05440522
A32: BELOW THE LINE
A33: Interest expense | B33: -411 | C33: -664 | D33: -629 | E33: ='Financing & D&A'!B14 -> -541.255 | F33: ='Financing & D&A'!C14 -> -541.255 | G33: ='Financing & D&A'!D14 -> -541.255 | H33: ='Financing & D&A'!E14 -> -541.255 | I33: ='Financing & D&A'!F14 -> -541.255 | J33: ='Financing & D&A'!G14 -> -1367.7959 | K33: ='Financing & D&A'!H14 -> -2431.9565 | L33: ='Financing & D&A'!I14 -> -2864.5824 | ... N33: ='Financing & D&A'!K14 -> -3417.7727
A34: Interest income | B34: 98 | C34: 213 | D34: 340 | E34: ='Financing & D&A'!B12 -> 1000.09 | F34: ='Financing & D&A'!C12 -> 884.75057 | G34: ='Financing & D&A'!D12 -> 781.11065 | H34: ='Financing & D&A'!E12 -> 581.27328 | I34: ='Financing & D&A'!F12 -> 217.86923 | J34: ='Financing & D&A'!G12 -> 150 | K34: ='Financing & D&A'!H12 -> 150 | L34: ='Financing & D&A'!I12 -> 150 | ... N34: ='Financing & D&A'!K12 -> 150
A35: Other income (expense), net | B35: 413 | C35: -1876 | D35: -86 | E35: =Assumptions!B73 -> -50 | F35: =Assumptions!C73 -> -50 | G35: =Assumptions!D73 -> -30 | H35: =Assumptions!E73 -> -20 | I35: =Assumptions!F73 -> -10 | J35: =Assumptions!G73 -> 0 | K35: =Assumptions!H73 -> 0 | L35: =Assumptions!I73 -> 0 | ... N35: =Assumptions!K73 -> 0
A36: Loss before income taxes | B36: =B29+B33+B34+B35 -> -870 | C36: =C29+C33+C34+C35 -> -4270 | D36: =D29+D33+D34+D35 -> -518 | E36: =E29+E33+E34+E35 -> 59.0172 | F36: =F29+F33+F34+F35 -> 592.84901 | G36: =G29+G33+G34+G35 -> 806.65688 | H36: =H29+H33+H34+H35 -> 1283.4457 | I36: =I29+I33+I34+I35 -> 1730.476 | ... N36: =N29+N33+N34+N35 -> -430.71423
A37: Provision for income taxes | B37: 138 | C37: 6 | D37: 23 | E37: =Assumptions!B74 -> 20 | F37: =Assumptions!C74 -> 20 | G37: =Assumptions!D74 -> 20 | H37: =Assumptions!E74 -> 20 | I37: =Assumptions!F74 -> 20 | J37: =Assumptions!G74 -> 20 | K37: =Assumptions!H74 -> 20 | L37: =Assumptions!I74 -> 20 | ... N37: =Assumptions!K74 -> 20
A38: Net income (loss) | B38: =B36-B37 -> -1008 | C38: =C36-C37 -> -4276 | D38: =D36-D37 -> -541 | E38: =E36-E37 -> 39.0172 | F38: =F36-F37 -> 572.84901 | G38: =G36-G37 -> 786.65688 | H38: =H36-H37 -> 1263.4457 | I38: =I36-I37 -> 1710.476 | ... N38: =N36-N37 -> -450.71423
A39: Net margin % | B39: =B38/B9 -> -0.24760501 | C39: =C38/C9 -> -0.91095015 | D39: =D38/D9 -> -0.069234707 | E39: =E38/E9 -> 0.0034007667 | F39: =F38/F9 -> 0.03842525 | G39: =G38/G9 -> 0.043000227 | H39: =H38/H9 -> 0.054105169 | I39: =I38/I9 -> 0.055663174 | ... N39: =N38/N9 -> -0.0086431802
A41: ADJUSTED EBITDA (memo)
A42: Adjusted EBITDA | B42: 1214 | C42: 1127 | D42: 3538 | E42: =E29+E26+Assumptions!$B$61 -> 3331.1822 | F42: =F29+F26+Assumptions!$B$61 -> 3980.3534 | G42: =G29+G26+Assumptions!$B$61 -> 4895.4253 | H42: =H29+H26+Assumptions!$B$61 -> 6154.0037 | I42: =I29+I26+Assumptions!$B$61 -> 7967.3627 | J42: =J29+J26+Assumptions!$B$61 -> 10604.843 | K42: =K29+K26+Assumptions!$B$61 -> 13063.073 | L42: =L29+L26+Assumptions!$B$61 -> 15028.1 | ... N42: =N29+N26+Assumptions!$B$61 -> 19073.595
A43: Forecast Adjusted EBITDA = operating income + new-capex depreciation + the legacy non-cash addback held flat from Q2'26A. Now computable because depreciation is an explicit line.
A45: IMPLIED MARKET CAP (memo — cloud computing comps)
A46: LTM revenue (trailing 4 quarters) | F46: =SUM(C9:F9) -> 38889.2 | G46: =SUM(D9:G9) -> 52489.449 | H46: =SUM(E9:H9) -> 68027.113 | I46: =SUM(F9:I9) -> 87283.094 | J46: =SUM(G9:J9) -> 111568.35 | K46: =SUM(H9:K9) -> 136410.67 | L46: =SUM(I9:L9) -> 159981.35 | M46: =SUM(J9:M9) -> 178480.24 | N46: =SUM(K9:N9) -> 191433.64
...

Sheet Financing & D&A
A1: Depreciation & Financing Schedule
A2: $ in millions. Forecast quarters only. Drives the depreciation and interest lines on the Consolidated P&L.
A4: $mm | B4: Q3'26E | C4: Q4'26E | D4: Q1'27E | E4: Q2'27E | F4: Q3'27E | G4: Q4'27E | H4: Q1'28E | I4: Q2'28E | J4: Q3'28E | K4: Q4'28E
A5: DEPRECIATION ON NEW FORECAST-PERIOD CAPEX
A6: Total capex in quarter (vintage) | B6: ='Consolidated P&L'!E63 -> 15303.96 | C6: ='Consolidated P&L'!F63 -> 14667.841 | D6: ='Consolidated P&L'!G63 -> 25099.018 | E6: ='Consolidated P&L'!H63 -> 42514.427 | F6: ='Consolidated P&L'!I63 -> 65274.957 | G6: ='Consolidated P&L'!J63 -> 74853.85 | H6: ='Consolidated P&L'!K63 -> 37384.249 | I6: ='Consolidated P&L'!L63 -> 36012.332 | ... K6: ='Consolidated P&L'!N63 -> 24206.66
A7: Quarterly depreciation from this vintage | B7: =B6*(Assumptions!$B$57/Assumptions!$B$58+(1-Assumptions!$B$57)/Assumptions!$B$59) -> 617.6241 | C7: =C6*(Assumptions!$B$57/Assumptions!$B$58+(1-Assumptions!$B$57)/Assumptions!$B$59) -> 591.95217 | D7: =D6*(Assumptions!$B$57/Assumptions!$B$58+(1-Assumptions!$B$57)/Assumptions!$B$59) -> 1012.9247 | E7: =E6*(Assumptions!$B$57/Assumptions!$B$58+(1-Assumptions!$B$57)/Assumptions!$B$59) -> 1715.7608 | F7: =F6*(Assumptions!$B$57/Assumptions!$B$58+(1-Assumptions!$B$57)/Assumptions!$B$59) -> 2634.3108 | G7: =G6*(Assumptions!$B$57/Assumptions!$B$58+(1-Assumptions!$B$57)/Assumptions!$B$59) -> 3020.8875 | H7: =H6*(Assumptions!$B$57/Assumptions!$B$58+(1-Assumptions!$B$57)/Assumptions!$B$59) -> 1508.7215 | I7: =I6*(Assumptions!$B$57/Assumptions!$B$58+(1-Assumptions!$B$57)/Assumptions!$B$59) -> 1453.3548 | ... K7: =K6*(Assumptions!$B$57/Assumptions!$B$58+(1-Assumptions!$B$57)/Assumptions!$B$59) -> 976.91163
A8: Depreciation on new capex (cumulative, in service) | B8: =0 -> 0 | C8: =0 -> 0 | D8: =C8+B7 -> 617.6241 | E8: =D8+C7 -> 1209.5763 | F8: =E8+D7 -> 2222.5009 | G8: =F8+E7 -> 3938.2617 | H8: =G8+F7 -> 6572.5725 | I8: =H8+G7 -> 9593.46 | J8: =I8+H7 -> 11102.181 | K8: =J8+I7 -> 12555.536
A10: CASH, DEBT & INTEREST
A11: Opening cash & securities | B11: =Assumptions!$B$68 -> 100009 | C11: =B22 -> 88475.057 | D11: =C22 -> 78111.065 | E11: =D22 -> 58127.328 | F11: =E22 -> 21786.923 | G11: =F22 -> 15000 | H11: =G22 -> 15000 | I11: =H22 -> 15000 | J11: =I22 -> 15000 | K11: =J22 -> 15000
A12: Interest income (opening cash x yield) | B12: =B11*Assumptions!$B$65/4 -> 1000.09 | C12: =C11*Assumptions!$B$65/4 -> 884.75057 | D12: =D11*Assumptions!$B$65/4 -> 781.11065 | E12: =E11*Assumptions!$B$65/4 -> 581.27328 | F12: =F11*Assumptions!$B$65/4 -> 217.86923 | G12: =G11*Assumptions!$B$65/4 -> 150 | H12: =H11*Assumptions!$B$65/4 -> 150 | I12: =I11*Assumptions!$B$65/4 -> 150 | ... K12: =K11*Assumptions!$B$65/4 -> 150
A13: Opening NEW debt balance | B13: =0 -> 0 | C13: =B23 -> 0 | D13: =C23 -> 0 | E13: =D23 -> 0 | F13: =E23 -> 0 | G13: =F23 -> 50864.057 | H13: =G23 -> 116350.86 | I13: =H23 -> 142973.99 | J13: =I23 -> 166692.81 | K13: =J23 -> 177016.47
A14: Interest expense (existing + new debt) | B14: =-(Assumptions!$B$62*Assumptions!$B$63/4+B13*Assumptions!$B$64/4) -> -541.255 | C14: =-(Assumptions!$B$62*Assumptions!$B$63/4+C13*Assumptions!$B$64/4) -> -541.255 | D14: =-(Assumptions!$B$62*Assumptions!$B$63/4+D13*Assumptions!$B$64/4) -> -541.255 | E14: =-(Assumptions!$B$62*Assumptions!$B$63/4+E13*Assumptions!$B$64/4) -> -541.255 | F14: =-(Assumptions!$B$62*Assumptions!$B$63/4+F13*Assumptions!$B$64/4) -> -541.255 | G14: =-(Assumptions!$B$62*Assumptions!$B$63/4+G13*Assumptions!$B$64/4) -> -1367.7959 | H14: =-(Assumptions!$B$62*Assumptions!$B$63/4+H13*Assumptions!$B$64/4) -> -2431.9565 | I14: =-(Assumptions!$B$62*Assumptions!$B$63/4+I13*Assumptions!$B$64/4) -> -2864.5824 | ... K14: =-(Assumptions!$B$62*Assumptions!$B$63/4+K13*Assumptions!$B$64/4) -> -3417.7727
A15: Operating income before new-capex D&A | B15: ='Consolidated P&L'!E25 -> -349.8178 | C15: ='Consolidated P&L'!F25 -> 299.35344 | D15: ='Consolidated P&L'!G25 -> 1214.4253 | E15: ='Consolidated P&L'!H25 -> 2473.0037 | F15: ='Consolidated P&L'!I25 -> 4286.3627 | G15: ='Consolidated P&L'!J25 -> 6923.8435 | H15: ='Consolidated P&L'!K25 -> 9382.0729 | I15: ='Consolidated P&L'!L25 -> 11347.1 | ... K15: ='Consolidated P&L'!N25 -> 15392.595
A16: Add back: legacy non-cash charges | B16: =Assumptions!$B$61 -> 3681 | C16: =Assumptions!$B$61 -> 3681 | D16: =Assumptions!$B$61 -> 3681 | E16: =Assumptions!$B$61 -> 3681 | F16: =Assumptions!$B$61 -> 3681 | G16: =Assumptions!$B$61 -> 3681 | H16: =Assumptions!$B$61 -> 3681 | I16: =Assumptions!$B$61 -> 3681 | ... K16: =Assumptions!$B$61 -> 3681
A17: Less: cash taxes | B17: =-Assumptions!B74 -> -20 | C17: =-Assumptions!C74 -> -20 | D17: =-Assumptions!D74 -> -20 | E17: =-Assumptions!E74 -> -20 | F17: =-Assumptions!F74 -> -20 | G17: =-Assumptions!G74 -> -20 | H17: =-Assumptions!H74 -> -20 | I17: =-Assumptions!I74 -> -20 | ... K17: =-Assumptions!K74 -> -20
A18: Operating cash flow (proxy) | B18: =B15+B16+B17+B12+B14 -> 3770.0172 | C18: =C15+C16+C17+C12+C14 -> 4303.849 | D18: =D15+D16+D17+D12+D14 -> 5115.281 | E18: =E15+E16+E17+E12+E14 -> 6174.022 | F18: =F15+F16+F17+F12+F14 -> 7623.9769 | G18: =G15+G16+G17+G12+G14 -> 9367.0475 | H18: =H15+H16+H17+H12+H14 -> 10761.116 | I18: =I15+I16+I17+I12+I14 -> 12293.518 | ... K18: =K15+K16+K17+K12+K14 -> 15785.822
A19: Less: capex | B19: =-B6 -> -15303.96 | C19: =-C6 -> -14667.841 | D19: =-D6 -> -25099.018 | E19: =-E6 -> -42514.427 | F19: =-F6 -> -65274.957 | G19: =-G6 -> -74853.85 | H19: =-H6 -> -37384.249 | I19: =-I6 -> -36012.332 | ... K19: =-K6 -> -24206.66
A20: Cash before financing | B20: =B11+B18+B19 -> 88475.057 | C20: =C11+C18+C19 -> 78111.065 | D20: =D11+D18+D19 -> 58127.328 | E20: =E11+E18+E19 -> 21786.923 | F20: =F11+F18+F19 -> -35864.057 | G20: =G11+G18+G19 -> -50486.803 | H20: =H11+H18+H19 -> -11623.132 | I20: =I11+I18+I19 -> -8718.8146 | ... K20: =K11+K18+K19 -> 6579.1621
A21: New debt drawn to hold minimum cash | B21: =MAX(0,Assumptions!$B$66-B20) -> 0 | C21: =MAX(0,Assumptions!$B$66-C20) -> 0 | D21: =MAX(0,Assumptions!$B$66-D20) -> 0 | E21: =MAX(0,Assumptions!$B$66-E20) -> 0 | F21: =MAX(0,Assumptions!$B$66-F20) -> 50864.057 | G21: =MAX(0,Assumptions!$B$66-G20) -> 65486.803 | H21: =MAX(0,Assumptions!$B$66-H20) -> 26623.132 | I21: =MAX(0,Assumptions!$B$66-I20) -> 23718.815 | ... K21: =MAX(0,Assumptions!$B$66-K20) -> 8420.8379
A22: Closing cash & securities | B22: =B20+B21 -> 88475.057 | C22: =C20+C21 -> 78111.065 | D22: =D20+D21 -> 58127.328 | E22: =E20+E21 -> 21786.923 | F22: =F20+F21 -> 15000 | G22: =G20+G21 -> 15000 | H22: =H20+H21 -> 15000 | I22: =I20+I21 -> 15000 | ... K22: =K20+K21 -> 15000
A23: Closing NEW debt balance | B23: =B13+B21 -> 0 | C23: =C13+C21 -> 0 | D23: =D13+D21 -> 0 | E23: =E13+E21 -> 0 | F23: =F13+F21 -> 50864.057 | G23: =G13+G21 -> 116350.86 | H23: =H13+H21 -> 142973.99 | I23: =I13+I21 -> 166692.81 | ... K23: =K13+K21 -> 185437.31
A24: Total debt outstanding (existing + new) | B24: =Assumptions!$B$62+B23 -> 39364 | C24: =Assumptions!$B$62+C23 -> 39364 | D24: =Assumptions!$B$62+D23 -> 39364 | E24: =Assumptions!$B$62+E23 -> 39364 | F24: =Assumptions!$B$62+F23 -> 90228.057 | G24: =Assumptions!$B$62+G23 -> 155714.86 | H24: =Assumptions!$B$62+H23 -> 182337.99 | I24: =Assumptions!$B$62+I23 -> 206056.81 | ... K24: =Assumptions!$B$62+K23 -> 224801.31
A25: Memo: cumulative new debt raised | B25: =B23 -> 0 | C25: =C23 -> 0 | D25: =D23 -> 0 | E25: =E23 -> 0 | F25: =F23 -> 50864.057 | G25: =G23 -> 116350.86 | H25: =H23 -> 142973.99 | I25: =I23 -> 166692.81 | ... K25: =K23 -> 185437.31
A27: QUARTERLY FREE CASH FLOW
A28: EBITDA (op income before new-capex D&A + legacy non-cash) | B28: =B15+B16 -> 3331.1822 | C28: =C15+C16 -> 3980.3534 | D28: =D15+D16 -> 4895.4253 | E28: =E15+E16 -> 6154.0037 | F28: =F15+F16 -> 7967.3627 | G28: =G15+G16 -> 10604.843 | H28: =H15+H16 -> 13063.073 | I28: =I15+I16 -> 15028.1 | ... K28: =K15+K16 -> 19073.595
A29: Less: cash taxes | B29: =B17 -> -20 | C29: =C17 -> -20 | D29: =D17 -> -20 | E29: =E17 -> -20 | F29: =F17 -> -20 | G29: =G17 -> -20 | H29: =H17 -> -20 | I29: =I17 -> -20 | ... K29: =K17 -> -20
A30: Less: capex | B30: =B19 -> -15303.96 | C30: =C19 -> -14667.841 | D30: =D19 -> -25099.018 | E30: =E19 -> -42514.427 | F30: =F19 -> -65274.957 | G30: =G19 -> -74853.85 | H30: =H19 -> -37384.249 | I30: =I19 -> -36012.332 | ... K30: =K19 -> -24206.66
A31: UNLEVERED FREE CASH FLOW | B31: =B28+B29+B30 -> -11992.778 | C31: =C28+C29+C30 -> -10707.488 | D31: =D28+D29+D30 -> -20223.593 | E31: =E28+E29+E30 -> -36380.423 | F31: =F28+F29+F30 -> -57327.594 | G31: =G28+G29+G30 -> -64269.007 | H31: =H28+H29+H30 -> -24341.176 | I31: =I28+I29+I30 -> -21004.232 | ... K31: =K28+K29+K30 -> -5153.0652
A32: Levered free cash flow (after interest) | B32: =B31+B14+B12 -> -11533.943 | C32: =C31+C14+C12 -> -10363.992 | D32: =D31+D14+D12 -> -19983.737 | E32: =E31+E14+E12 -> -36340.405 | F32: =F31+F14+F12 -> -57650.98 | G32: =G31+G14+G12 -> -65486.803 | H32: =H31+H14+H12 -> -26623.132 | I32: =I31+I14+I12 -> -23718.815 | ... K32: =K31+K14+K12 -> -8420.8379
A33: Excludes working capital and deferred revenue movements, which have historically been a source of cash for SpaceX. Unlevered FCF is the input to the DCF below.
A35: CREDIT CHECKS
A36: EBITDA / interest expense (coverage, x) | B36: =IFERROR(B28/-B14,"n/m") -> 6.1545523 | C36: =IFERROR(C28/-C14,"n/m") -> 7.3539338 | D36: =IFERROR(D28/-D14,"n/m") -> 9.0445822 | E36: =IFERROR(E28/-E14,"n/m") -> 11.369879 | F36: =IFERROR(F28/-F14,"n/m") -> 14.720165 | G36: =IFERROR(G28/-G14,"n/m") -> 7.7532351 | H36: =IFERROR(H28/-H14,"n/m") -> 5.3714254 | I36: =IFERROR(I28/-I14,"n/m") -> 5.2461749 | ... K36: =IFERROR(K28/-K14,"n/m") -> 5.580709
A37: Total debt / annualised EBITDA (leverage, x) | B37: =IFERROR(B24/(B28*4),"n/m") -> 2.9542065 | C37: =IFERROR(C24/(C28*4),"n/m") -> 2.4723935 | D37: =IFERROR(D24/(D28*4),"n/m") -> 2.0102441 | E37: =IFERROR(E24/(E28*4),"n/m") -> 1.5991216 | F37: =IFERROR(F24/(F28*4),"n/m") -> 2.831177 | G37: =IFERROR(G24/(G28*4),"n/m") -> 3.670843 | H37: =IFERROR(H24/(H28*4),"n/m") -> 3.4895693 | I37: =IFERROR(I24/(I28*4),"n/m") -> 3.4278586 | ... K37: =IFERROR(K24/(K28*4),"n/m") -> 2.946499
A38: Leverage within a 6.0x investment-grade-ish ceiling? | B38: =IF(ISNUMBER(B37),IF(B37<=6,"Yes","NO"),"n/m") -> Yes | C38: =IF(ISNUMBER(C37),IF(C37<=6,"Yes","NO"),"n/m") -> Yes | D38: =IF(ISNUMBER(D37),IF(D37<=6,"Yes","NO"),"n/m") -> Yes | E38: =IF(ISNUMBER(E37),IF(E37<=6,"Yes","NO"),"n/m") -> Yes | F38: =IF(ISNUMBER(F37),IF(F37<=6,"Yes","NO"),"n/m") -> Yes | G38: =IF(ISNUMBER(G37),IF(G37<=6,"Yes","NO"),"n/m") -> Yes | H38: =IF(ISNUMBER(H37),IF(H37<=6,"Yes","NO"),"n/m") -> Yes | I38: =IF(ISNUMBER(I37),IF(I37<=6,"Yes","NO"),"n/m") -> Yes | ... K38: =IF(ISNUMBER(K37),IF(K37<=6,"Yes","NO"),"n/m") -> Yes
A39: A 6.0x net-debt/EBITDA ceiling is a rough high-yield covenant marker, not a rating agency threshold. Where this reads NO, the capex plan is not fundable with debt alone on these earnings and would require equity or partner/SPV structures of the kind CoreWeave uses.
A41: DCF (read the terminal-value warning below before using this)
A42: WACC (annual) | B42: 0.115
A43: Terminal growth rate | B43: 0.04
A44: Normalised terminal-year FCF ($mm/yr) | B44: 40000
A45: PV of forecast unlevered FCF (Q3'26E-Q4'28E) | B45: =B31/(1+$B$42/4)^1+C31/(1+$B$42/4)^2+D31/(1+$B$42/4)^3+E31/(1+$B$42/4)^4+F31/(1+$B$42/4)^5+G31/(1+$B$42/4)^6+H31/(1+$B$42/4)^7+I31/(1+$B$42/4)^8+J31/(1+$B$42/4)^9+K31/(1+$B$42/4)^10 -> -222982.97
...

Sheet Balance Sheet & CF
A1: Balance Sheet & Cash Flow (Actuals)
A2: $ in millions. Source: SpaceX Q2 2026 earnings release, Consolidated Balance Sheets and Selected Cash Flow Information
A4: Balance Sheet, $mm | B4: Jun 30, 2026 | C4: Dec 31, 2025
A5: ASSETS
A6: Cash and cash equivalents | B6: 93522 | C6: 24747
A7: Marketable securities | B7: 6487 | C7: 0
A8: Accounts receivable, net | B8: 3596 | C8: 1579
A9: Inventory | B9: 2718 | C9: 2416
A10: Prepaid expenses and other current assets | B10: 1724 | C10: 2210
A11: Total current assets | B11: =SUM(B6:B10) -> 108047 | C11: =SUM(C6:C10) -> 30952
A12: Property, plant, and equipment, net | B12: 65736 | C12: 42602
A13: Finance lease right-of-use assets | B13: 1118 | C13: 1260
A14: Intangible assets, net | B14: 1318 | C14: 1548
A15: Digital assets | B15: 1098 | C15: 1637
A16: Goodwill | B16: 11645 | C16: 11809
A17: Deferred tax assets | B17: 354 | C17: 141
A18: Other assets | B18: 3454 | C18: 2130
A19: Total assets | B19: =B11+SUM(B12:B18) -> 192770 | C19: =C11+SUM(C12:C18) -> 92079
A21: LIABILITIES
A22: Accounts payable | B22: 8243 | C22: 11792
A23: Deferred revenue, current | B23: 7977 | C23: 6111
A24: Debt and finance leases, current | B24: 2525 | C24: 928
A25: Accrued expenses and other current liabilities | B25: 2377 | C25: 2569
A26: Total current liabilities | B26: =SUM(B22:B25) -> 21122 | C26: =SUM(C22:C25) -> 21400
A27: Deferred revenue, net of current | B27: 6309 | C27: 6005
A28: Debt and finance leases, net of current | B28: 36839 | C28: 21968
A29: Other liabilities | B29: 1276 | C29: 1381
A30: Total liabilities | B30: =B26+SUM(B27:B29) -> 65546 | C30: =C26+SUM(C27:C29) -> 50754
A32: REDEEMABLE CONVERTIBLE PREFERRED STOCK & EQUITY
A33: Redeemable convertible preferred stock | B33: 0 | C33: 38752
A34: Total shareholders' equity | B34: 127224 | C34: 2573
A35: Total liabilities, preferred stock & equity | B35: =B30+B33+B34 -> 192770 | C35: =C30+C33+C34 -> 92079
A36: Balance check (Assets - Liab&Equity) | B36: =B19-B35 -> 0 | C36: =C19-C35 -> 0
A39: Cash Flow (6 months ended June 30), $mm | B39: 2026 | C39: 2025
A40: Net cash provided by operating activities | B40: 3466 | C40: 351
A41: Net cash used in investing activities | B41: -34487 | C41: -6032
A42: Net cash provided by financing activities | B42: 100291 | C42: 9199
A43: Net change in cash & restricted cash | B43: =SUM(B40:B42) -> 69270 | C43: =SUM(C40:C42) -> 3518
A44: Cash & restricted cash, beginning of period | B44: 25124 | C44: 11501
A45: Cash & restricted cash, end of period | B45: =B43+B44 -> 94394 | C45: =C43+C44 -> 15019
...

Sheet Terrestrial vs Orbital
A1: Capex per GW of AI Compute: Terrestrial vs Orbital
A2: $ in millions per GW of AVERAGE compute power. Bottom-up build from SpaceX's disclosed AI1 specifications and published Starship launch economics. Memo/analysis tab — does not feed the forecast.
A4: $mm per GW (average compute) | B4: Terrestrial | C4: Orbital | E4: Basis / source
A5: PHYSICAL INPUTS (editable)
A6: Average compute power per satellite (kW) | B6: n/a | C6: 120 | E6: SpaceX AI1 disclosure (Jun 8, 2026): 150 kW peak, 120 kW average compute payload. Average is the right basis since revenue tracks delivered compute.
A7: Compute power density (kW per ton) | B7: n/a | C7: 70 | E7: AI1 disclosed spec: 70 kW per ton. Musk's forward-looking claim of 100 kW/ton is tested in the sensitivity grid below.
A8: Launch cost ($ per kg to LEO) | B8: n/a | C8: 200 | E8: Starship target range is roughly $100-500/kg once fully reusable; Musk's aspiration is ~$10/kg. Falcon 9 today is ~$2,700-3,000/kg. $200/kg used as the base case.
A9: Solar array cost ($ per W) | B9: n/a | C9: 1.5 | E9: AI1 carries a 150 kW array at 250 W/m², using SpaceX-manufactured cells from its Bastrop facility. Assumes mass-production economics well below traditional space-solar costs.
A10: Radiator cost ($ per m2) | B10: n/a | C10: 4000 | E10: AI1 carries a 110 m² deployable liquid radiator with redundant pumping loops and micrometeoroid shielding.
A11: Radiator area per satellite (m2) | B11: n/a | C11: 110 | E11: AI1 disclosed spec.
A12: Satellite bus / structure / integration ($mm each) | B12: n/a | C12: 1.2 | E12: Structure, avionics, propulsion, deployment mechanisms and assembly, excluding compute, solar and radiator. Benchmarked up from Starlink V2 unit economics for a larger, more complex spacecraft.
A13: Space-qualification premium on compute hardware | B13: n/a | C13: 1.3 | E13: Radiation tolerance, thermal packaging and lower production volumes versus commodity data-centre racks.
A14: Compute hardware cost, terrestrial basis ($mm per GW) | B14: 23000 | C14: n/a | E14: Epoch AI puts servers/GPUs at ~60% of a $38B/GW build; Bernstein's rack build-up ($3.4M compute of a $5.9M GB200 NVL72 rack) implies ~$24B/GW. Orbital applies the premium above to this same figure.
A15: Building, land & site works ($mm per GW) | B15: 4000 | C15: 0 | E15: Eliminated in orbit — no land, no shell, no zoning.
A16: Grid power delivery & backup ($mm per GW) | B16: 6500 | C16: 0 | E16: Substation, transformers, UPS and backup generation. Eliminated in orbit: the solar array below replaces it, and sunlight is free.
A17: Cooling plant & water systems ($mm per GW) | B17: 4500 | C17: 0 | E17: Chillers, CRAHs, liquid loops and water infrastructure. Eliminated in orbit: replaced by the radiator line below, though vacuum makes heat rejection harder, not easier, per unit area.
A18: Ground segment / optical links ($mm per GW) | B18: 0 | C18: 1500 | E18: Orbital needs laser inter-satellite links and ground gateways to move data; terrestrial fibre is assumed included in site works.
A20: DERIVED PHYSICAL QUANTITIES (orbital)
A21: Satellites required per GW | B21: n/a | C21: =1000000/C6 -> 8333.3333 | E21: 1 GW of average compute divided by 120 kW per satellite. Musk noted one AI1 is roughly equivalent to a single NVIDIA GB300 rack.
A22: Mass to orbit per GW (metric tons) | B22: n/a | C22: =1000000/C7 -> 14285.714 | E22: 1 GW divided by 70 kW/ton. For scale, this is well above SpaceX's total mass launched to date in a year — the build-out is launch-cadence constrained, not just capital constrained.
A24: CAPEX BUILD-UP PER GW
A25: Compute hardware | B25: =B14 -> 23000 | C25: =B14*C13 -> 29900 | E25: The dominant cost on both sides, and the one orbital cannot avoid.
A26: Building, land & site works | B26: =B15 -> 4000 | C26: =C15 -> 0 | E26: Orbital saving.
A27: Grid power delivery & backup | B27: =B16 -> 6500 | C27: =C16 -> 0 | E27: Orbital saving — this is the 'free energy' advantage in capex terms.
A28: Cooling plant & water systems | B28: =B17 -> 4500 | C28: =C17 -> 0 | E28: Orbital saving on paper, but see the radiator line — heat rejection is replaced, not removed.
A29: Solar array (replaces grid power) | B29: =0 -> 0 | C29: =C21*150*1000*C9/1000000 -> 1875 | E29: 150 kW array per satellite at the $/W input. This is the capex you pay to get 'free' energy.
A30: Deployable radiators (replace cooling) | B30: =0 -> 0 | C30: =C21*C11*C10/1000000 -> 3666.6667 | E30: 110 m² per satellite. Vacuum removes water and chiller cost but radiative heat rejection needs large deployable area — several independent analyses argue AI1's disclosed radiator area is the binding physical constraint on the design.
A31: Satellite bus, structure & integration | B31: =0 -> 0 | C31: =C21*C12 -> 10000 | E31: No terrestrial analogue — this is pure incremental cost for orbital.
A32: Launch to LEO | B32: =0 -> 0 | C32: =C22*C8/1000 -> 2857.1429 | E32: Mass per GW times $/kg. Notably NOT the dominant term at Starship target pricing.
A33: Ground segment / optical links | B33: =B18 -> 0 | C33: =C18 -> 1500 | E33: Orbital-only cost.
A34: TOTAL CAPEX PER GW | B34: =SUM(B25:B33) -> 38000 | C34: =SUM(C25:C33) -> 49798.81 | E34: Cross-check: Epoch AI's independent 1 GW model lands at $38B for terrestrial; Bernstein $35B, Nvidia $50-60B, Orennia $60B. The orbital figure has no external benchmark — it is built from SpaceX's own disclosed specs.
A35: Orbital as a multiple of terrestrial | C35: =C34/B34 -> 1.310495
A37: ANNUALIZED COST OF OWNERSHIP PER GW (where free energy actually shows up)
A38: Compute hardware life (years) | B38: 5 | C38: 5 | E38: Epoch AI assumes 5 years for IT equipment on the ground. Assumed equal in orbit — chip obsolescence, not wear, is the binding constraint.
A39: Infrastructure life (years) | B39: 14 | C39: 5 | E39: THE CRITICAL ASYMMETRY. A terrestrial building, substation and chiller plant serve ~14 years and multiple server refreshes. An orbital satellite cannot be serviced — refreshing the compute means relaunching the entire spacecraft, so ALL of it is written off on the compute cycle.
